<?xml version="1.0" encoding="UTF-8"?>
<!-- Generated by org.testng.reporters.JUnitXMLReporter -->
<testsuite hostname="hanbingdeMacBook-Air.local" ignored="0" name="Default test" tests="2" failures="1" timestamp="30 七月 2020 06:59:49 GMT" time="4.118" errors="0">
  <testcase name="testError" time="2.034" classname="con.course.code.Chapter5.TimeOutTest">
    <failure type="org.testng.internal.thread.ThreadTimeoutException" message="Method con.course.code.Chapter5.TimeOutTest.testError() didn&amp;apos;t finish within the time-out 2000">
      <![CDATA[org.testng.internal.thread.ThreadTimeoutException: Method con.course.code.Chapter5.TimeOutTest.testError() didn't finish within the time-out 2000
at java.util.concurrent.FutureTask.setException(FutureTask.java:248)
at java.util.concurrent.FutureTask.run(FutureTask.java:271)
at java.util.concurrent.ThreadPoolExecutor.runWorker(ThreadPoolExecutor.java:1149)
at java.util.concurrent.ThreadPoolExecutor$Worker.run(ThreadPoolExecutor.java:624)
at java.lang.Thread.run(Thread.java:748)
]]>
    </failure>
  </testcase> <!-- testError -->
  <testcase name="testSuccess" time="2.011" classname="con.course.code.Chapter5.TimeOutTest"/>
</testsuite> <!-- Default test -->
